C:\Users\brede\OneDrive - Atea\Data\Atea\ATimer\år2020\python\versjon2>pip install PyQt5
Collecting PyQt5
  Downloading PyQt5-5.15.2-5.15.2-cp35.cp36.cp37.cp38.cp39-none-win_amd64.whl (56.9 MB)
     |████████████████████████████████| 56.9 MB 212 kB/s
Collecting PyQt5-sip<13,>=12.8
  Downloading PyQt5_sip-12.8.1-cp38-cp38-win_amd64.whl (63 kB)
     |████████████████████████████████| 63 kB ...
Installing collected packages: PyQt5-sip, PyQt5
Successfully installed PyQt5-5.15.2 PyQt5-sip-12.8.1
WARNING: You are using pip version 20.2.3; however, version 20.3.3 is available.
You should consider upgrading via the 'c:\users\brede\appdata\local\programs\python\python38\python.exe -m pip install --upgrade pip' command.

C:\Users\brede\OneDrive - Atea\Data\Atea\ATimer\år2020\python\versjon2>c:\users\brede\appdata\local\programs\python\python38\python.exe -m pip install --upgrade pip
Collecting pip
  Downloading pip-20.3.3-py2.py3-none-any.whl (1.5 MB)
     |████████████████████████████████| 1.5 MB 819 kB/s
Installing collected packages: pip
  Attempting uninstall: pip
    Found existing installation: pip 20.2.3
    Uninstalling pip-20.2.3:
      Successfully uninstalled pip-20.2.3
Successfully installed pip-20.3.3

C:\Users\brede\OneDrive - Atea\Data\Atea\ATimer\år2020\python\versjon2>python RegTimerMain.py
Traceback (most recent call last):
  File "RegTimerMain.py", line 2, in <module>
    from ShowTimer import showtimer
  File "C:\Users\brede\OneDrive - Atea\Data\Atea\ATimer\år2020\python\versjon2\ShowTimer.py", line 4, in <module>
    from dbsqlite import timedb
  File "C:\Users\brede\OneDrive - Atea\Data\Atea\ATimer\år2020\python\versjon2\dbsqlite.py", line 2, in <module>
    import yaml
ModuleNotFoundError: No module named 'yaml'

C:\Users\brede\OneDrive - Atea\Data\Atea\ATimer\år2020\python\versjon2>pip install yaml
ERROR: Could not find a version that satisfies the requirement yaml
ERROR: No matching distribution found for yaml

C:\Users\brede\OneDrive - Atea\Data\Atea\ATimer\år2020\python\versjon2>pip install pyyaml
Collecting pyyaml
  Downloading PyYAML-5.3.1-cp38-cp38-win_amd64.whl (219 kB)
     |████████████████████████████████| 219 kB 1.6 MB/s
Installing collected packages: pyyaml
Successfully installed pyyaml-5.3.1

C:\Users\brede\OneDrive - Atea\Data\Atea\ATimer\år2020\python\versjon2>python RegTimerMain.py
Traceback (most recent call last):
  File "RegTimerMain.py", line 2, in <module>
    from ShowTimer import showtimer
  File "C:\Users\brede\OneDrive - Atea\Data\Atea\ATimer\år2020\python\versjon2\ShowTimer.py", line 4, in <module>
    from dbsqlite import timedb
  File "C:\Users\brede\OneDrive - Atea\Data\Atea\ATimer\år2020\python\versjon2\dbsqlite.py", line 4, in <module>
    import pandas as pd
ModuleNotFoundError: No module named 'pandas'

C:\Users\brede\OneDrive - Atea\Data\Atea\ATimer\år2020\python\versjon2>pip install pandas
Collecting pandas
  Downloading pandas-1.2.0-cp38-cp38-win_amd64.whl (9.3 MB)
     |████████████████████████████████| 9.3 MB 1.3 MB/s
Collecting numpy>=1.16.5
  Downloading numpy-1.19.4-cp38-cp38-win_amd64.whl (13.0 MB)
     |████████████████████████████████| 13.0 MB 2.2 MB/s
Collecting python-dateutil>=2.7.3
  Downloading python_dateutil-2.8.1-py2.py3-none-any.whl (227 kB)
     |████████████████████████████████| 227 kB 6.8 MB/s
Collecting pytz>=2017.3
  Downloading pytz-2020.5-py2.py3-none-any.whl (510 kB)
     |████████████████████████████████| 510 kB 6.4 MB/s
Collecting six>=1.5
  Downloading six-1.15.0-py2.py3-none-any.whl (10 kB)
Installing collected packages: six, pytz, python-dateutil, numpy, pandas
Successfully installed numpy-1.19.4 pandas-1.2.0 python-dateutil-2.8.1 pytz-2020.5 six-1.15.0

C:\Users\brede\OneDrive - Atea\Data\Atea\ATimer\år2020\python\versjon2>python RegTimerMain.py
 ** On entry to DGEBAL parameter number  3 had an illegal value
 ** On entry to DGEHRD  parameter number  2 had an illegal value
 ** On entry to DORGHR DORGQR parameter number  2 had an illegal value
 ** On entry to DHSEQR parameter number  4 had an illegal value
Traceback (most recent call last):
  File "RegTimerMain.py", line 2, in <module>
    from ShowTimer import showtimer
  File "C:\Users\brede\OneDrive - Atea\Data\Atea\ATimer\år2020\python\versjon2\ShowTimer.py", line 4, in <module>
    from dbsqlite import timedb
  File "C:\Users\brede\OneDrive - Atea\Data\Atea\ATimer\år2020\python\versjon2\dbsqlite.py", line 4, in <module>
    import pandas as pd
  File "C:\Users\brede\AppData\Local\Programs\Python\Python38\lib\site-packages\pandas\__init__.py", line 11, in <module>
    __import__(dependency)
  File "C:\Users\brede\AppData\Local\Programs\Python\Python38\lib\site-packages\numpy\__init__.py", line 305, in <module>
    _win_os_check()
  File "C:\Users\brede\AppData\Local\Programs\Python\Python38\lib\site-packages\numpy\__init__.py", line 302, in _win_os_check
    raise RuntimeError(msg.format(__file__)) from None
RuntimeError: The current Numpy installation ('C:\\Users\\brede\\AppData\\Local\\Programs\\Python\\Python38\\lib\\site-packages\\numpy\\__init__.py') fails to pass a sanity check due to a bug in the windows runtime. See this issue for more information: https://tinyurl.com/y3dm3h86

C:\Users\brede\OneDrive - Atea\Data\Atea\ATimer\år2020\python\versjon2>python RegTimerMain.py
 ** On entry to DGEBAL parameter number  3 had an illegal value
 ** On entry to DGEHRD  parameter number  2 had an illegal value
 ** On entry to DORGHR DORGQR parameter number  2 had an illegal value
 ** On entry to DHSEQR parameter number  4 had an illegal value
Traceback (most recent call last):
  File "RegTimerMain.py", line 2, in <module>
    from ShowTimer import showtimer
  File "C:\Users\brede\OneDrive - Atea\Data\Atea\ATimer\år2020\python\versjon2\ShowTimer.py", line 4, in <module>
    from dbsqlite import timedb
  File "C:\Users\brede\OneDrive - Atea\Data\Atea\ATimer\år2020\python\versjon2\dbsqlite.py", line 4, in <module>
    import pandas as pd
  File "C:\Users\brede\AppData\Local\Programs\Python\Python38\lib\site-packages\pandas\__init__.py", line 11, in <module>
    __import__(dependency)
  File "C:\Users\brede\AppData\Local\Programs\Python\Python38\lib\site-packages\numpy\__init__.py", line 305, in <module>
    _win_os_check()
  File "C:\Users\brede\AppData\Local\Programs\Python\Python38\lib\site-packages\numpy\__init__.py", line 302, in _win_os_check
    raise RuntimeError(msg.format(__file__)) from None
RuntimeError: The current Numpy installation ('C:\\Users\\brede\\AppData\\Local\\Programs\\Python\\Python38\\lib\\site-packages\\numpy\\__init__.py') fails to pass a sanity check due to a bug in the windows runtime. See this issue for more information: https://tinyurl.com/y3dm3h86

C:\Users\brede\OneDrive - Atea\Data\Atea\ATimer\år2020\python\versjon2>pip install Numpy
Requirement already satisfied: Numpy in c:\users\brede\appdata\local\programs\python\python38\lib\site-packages (1.19.4)

C:\Users\brede\OneDrive - Atea\Data\Atea\ATimer\år2020\python\versjon2>python RegTimerMain.py
 ** On entry to DGEBAL parameter number  3 had an illegal value
 ** On entry to DGEHRD  parameter number  2 had an illegal value
 ** On entry to DORGHR DORGQR parameter number  2 had an illegal value
 ** On entry to DHSEQR parameter number  4 had an illegal value
Traceback (most recent call last):
  File "RegTimerMain.py", line 2, in <module>
    from ShowTimer import showtimer
  File "C:\Users\brede\OneDrive - Atea\Data\Atea\ATimer\år2020\python\versjon2\ShowTimer.py", line 4, in <module>
    from dbsqlite import timedb
  File "C:\Users\brede\OneDrive - Atea\Data\Atea\ATimer\år2020\python\versjon2\dbsqlite.py", line 4, in <module>
    import pandas as pd
  File "C:\Users\brede\AppData\Local\Programs\Python\Python38\lib\site-packages\pandas\__init__.py", line 11, in <module>
    __import__(dependency)
  File "C:\Users\brede\AppData\Local\Programs\Python\Python38\lib\site-packages\numpy\__init__.py", line 305, in <module>
    _win_os_check()
  File "C:\Users\brede\AppData\Local\Programs\Python\Python38\lib\site-packages\numpy\__init__.py", line 302, in _win_os_check
    raise RuntimeError(msg.format(__file__)) from None
RuntimeError: The current Numpy installation ('C:\\Users\\brede\\AppData\\Local\\Programs\\Python\\Python38\\lib\\site-packages\\numpy\\__init__.py') fails to pass a sanity check due to a bug in the windows runtime. See this issue for more information: https://tinyurl.com/y3dm3h86

C:\Users\brede\OneDrive - Atea\Data\Atea\ATimer\år2020\python\versjon2>pip uninstall numpy
Found existing installation: numpy 1.19.4
Uninstalling numpy-1.19.4:
  Would remove:
    c:\users\brede\appdata\local\programs\python\python38\lib\site-packages\numpy-1.19.4.dist-info\*
    c:\users\brede\appdata\local\programs\python\python38\lib\site-packages\numpy\*
    c:\users\brede\appdata\local\programs\python\python38\scripts\f2py.exe
Proceed (y/n)? y
  Successfully uninstalled numpy-1.19.4

C:\Users\brede\OneDrive - Atea\Data\Atea\ATimer\år2020\python\versjon2>pip install numpy==1.19.3
Collecting numpy==1.19.3
  Downloading numpy-1.19.3-cp38-cp38-win_amd64.whl (13.3 MB)
     |████████████████████████████████| 13.3 MB 6.4 MB/s
Installing collected packages: numpy
Successfully installed numpy-1.19.3

C:\Users\brede\OneDrive - Atea\Data\Atea\ATimer\år2020\python\versjon2>python RegTimerMain.py
Traceback (most recent call last):
  File "RegTimerMain.py", line 2, in <module>
    from ShowTimer import showtimer
  File "C:\Users\brede\OneDrive - Atea\Data\Atea\ATimer\år2020\python\versjon2\ShowTimer.py", line 7, in <module>
    import qdarkstyle
ModuleNotFoundError: No module named 'qdarkstyle'

C:\Users\brede\OneDrive - Atea\Data\Atea\ATimer\år2020\python\versjon2>pip install qdarkstyle
Collecting qdarkstyle
  Downloading QDarkStyle-2.8.1-py2.py3-none-any.whl (217 kB)
     |████████████████████████████████| 217 kB 6.4 MB/s
Collecting helpdev>=0.6.10
  Downloading helpdev-0.7.1-py3-none-any.whl (14 kB)
Collecting qtpy>=1.9
  Downloading QtPy-1.9.0-py2.py3-none-any.whl (54 kB)
     |████████████████████████████████| 54 kB ...
Installing collected packages: qtpy, helpdev, qdarkstyle
Successfully installed helpdev-0.7.1 qdarkstyle-2.8.1 qtpy-1.9.0

C:\Users\brede\OneDrive - Atea\Data\Atea\ATimer\år2020\python\versjon2>python RegTimerMain.py
Traceback (most recent call last):
  File "RegTimerMain.py", line 4, in <module>
    from Resultat import showresultat
  File "C:\Users\brede\OneDrive - Atea\Data\Atea\ATimer\år2020\python\versjon2\Resultat.py", line 7, in <module>
    from ResultatPlot import ResultatPlot
  File "C:\Users\brede\OneDrive - Atea\Data\Atea\ATimer\år2020\python\versjon2\ResultatPlot.py", line 2, in <module>
    import matplotlib.pyplot as plt
ModuleNotFoundError: No module named 'matplotlib'

C:\Users\brede\OneDrive - Atea\Data\Atea\ATimer\år2020\python\versjon2>pip install matplotlib
Collecting matplotlib
  Downloading matplotlib-3.3.3-cp38-cp38-win_amd64.whl (8.5 MB)
     |████████████████████████████████| 8.5 MB 2.2 MB/s
Requirement already satisfied: python-dateutil>=2.1 in c:\users\brede\appdata\local\programs\python\python38\lib\site-packages (from matplotlib) (2.8.1)
Requirement already satisfied: numpy>=1.15 in c:\users\brede\appdata\local\programs\python\python38\lib\site-packages (from matplotlib) (1.19.3)
Collecting cycler>=0.10
  Downloading cycler-0.10.0-py2.py3-none-any.whl (6.5 kB)
Requirement already satisfied: six in c:\users\brede\appdata\local\programs\python\python38\lib\site-packages (from cycler>=0.10->matplotlib) (1.15.0)
Collecting kiwisolver>=1.0.1
  Downloading kiwisolver-1.3.1-cp38-cp38-win_amd64.whl (51 kB)
     |████████████████████████████████| 51 kB ...
Collecting pillow>=6.2.0
  Downloading Pillow-8.0.1-cp38-cp38-win_amd64.whl (2.1 MB)
     |████████████████████████████████| 2.1 MB ...
Collecting pyparsing!=2.0.4,!=2.1.2,!=2.1.6,>=2.0.3
  Downloading pyparsing-2.4.7-py2.py3-none-any.whl (67 kB)
     |████████████████████████████████| 67 kB 1.8 MB/s
Installing collected packages: pyparsing, pillow, kiwisolver, cycler, matplotlib
Successfully installed cycler-0.10.0 kiwisolver-1.3.1 matplotlib-3.3.3 pillow-8.0.1 pyparsing-2.4.7

C:\Users\brede\OneDrive - Atea\Data\Atea\ATimer\år2020\python\versjon2>python RegTimerMain.py
no DB making new now !
Traceback (most recent call last):
  File "C:\Users\brede\OneDrive - Atea\Data\Atea\ATimer\år2020\python\versjon2\dbsqlite.py", line 639, in create_connection
    conn = sqlite3.connect(db_file)
sqlite3.OperationalError: unable to open database file

During handling of the above exception, another exception occurred:

Traceback (most recent call last):
  File "RegTimerMain.py", line 652, in <module>
    vindu = AppMainWindow()
  File "RegTimerMain.py", line 35, in __init__
    new_db = NewDatabase(self.db_file)
  File "C:\Users\brede\OneDrive - Atea\Data\Atea\ATimer\år2020\python\versjon2\dbsqlite.py", line 622, in __init__
    conn=self.create_connection(db_file)
  File "C:\Users\brede\OneDrive - Atea\Data\Atea\ATimer\år2020\python\versjon2\dbsqlite.py", line 641, in create_connection
    except conn.Error as e:
AttributeError: 'NoneType' object has no attribute 'Error'

C:\Users\brede\OneDrive - Atea\Data\Atea\ATimer\år2020\python\versjon2>python RegTimerMain.py
Traceback (most recent call last):
  File "RegTimerMain.py", line 652, in <module>
    vindu = AppMainWindow()
  File "RegTimerMain.py", line 27, in __init__
    data = yaml.load(f, Loader=yaml.FullLoader)
  File "C:\Users\brede\AppData\Local\Programs\Python\Python38\lib\site-packages\yaml\__init__.py", line 114, in load
    return loader.get_single_data()
  File "C:\Users\brede\AppData\Local\Programs\Python\Python38\lib\site-packages\yaml\constructor.py", line 49, in get_single_data
    node = self.get_single_node()
  File "C:\Users\brede\AppData\Local\Programs\Python\Python38\lib\site-packages\yaml\composer.py", line 36, in get_single_node
    document = self.compose_document()
  File "C:\Users\brede\AppData\Local\Programs\Python\Python38\lib\site-packages\yaml\composer.py", line 55, in compose_document
    node = self.compose_node(None, None)
  File "C:\Users\brede\AppData\Local\Programs\Python\Python38\lib\site-packages\yaml\composer.py", line 84, in compose_node
    node = self.compose_mapping_node(anchor)
  File "C:\Users\brede\AppData\Local\Programs\Python\Python38\lib\site-packages\yaml\composer.py", line 133, in compose_mapping_node
    item_value = self.compose_node(node, item_key)
  File "C:\Users\brede\AppData\Local\Programs\Python\Python38\lib\site-packages\yaml\composer.py", line 64, in compose_node
    if self.check_event(AliasEvent):
  File "C:\Users\brede\AppData\Local\Programs\Python\Python38\lib\site-packages\yaml\parser.py", line 98, in check_event
    self.current_event = self.state()
  File "C:\Users\brede\AppData\Local\Programs\Python\Python38\lib\site-packages\yaml\parser.py", line 449, in parse_block_mapping_value
    if not self.check_token(KeyToken, ValueToken, BlockEndToken):
  File "C:\Users\brede\AppData\Local\Programs\Python\Python38\lib\site-packages\yaml\scanner.py", line 116, in check_token
    self.fetch_more_tokens()
  File "C:\Users\brede\AppData\Local\Programs\Python\Python38\lib\site-packages\yaml\scanner.py", line 251, in fetch_more_tokens
    return self.fetch_double()
  File "C:\Users\brede\AppData\Local\Programs\Python\Python38\lib\site-packages\yaml\scanner.py", line 655, in fetch_double
    self.fetch_flow_scalar(style='"')
  File "C:\Users\brede\AppData\Local\Programs\Python\Python38\lib\site-packages\yaml\scanner.py", line 666, in fetch_flow_scalar
    self.tokens.append(self.scan_flow_scalar(style))
  File "C:\Users\brede\AppData\Local\Programs\Python\Python38\lib\site-packages\yaml\scanner.py", line 1149, in scan_flow_scalar
    chunks.extend(self.scan_flow_scalar_non_spaces(double, start_mark))
  File "C:\Users\brede\AppData\Local\Programs\Python\Python38\lib\site-packages\yaml\scanner.py", line 1213, in scan_flow_scalar_non_spaces
    raise ScannerError("while scanning a double-quoted scalar", start_mark,
yaml.scanner.ScannerError: while scanning a double-quoted scalar
  in "C:\Users\brede\OneDrive - Atea\Data\Atea\ATimer\år2020\python\versjon2\config.yml", line 1, column 10
expected escape sequence of 8 hexdecimal numbers, but found 's'
  in "C:\Users\brede\OneDrive - Atea\Data\Atea\ATimer\år2020\python\versjon2\config.yml", line 1, column 15

C:\Users\brede\OneDrive - Atea\Data\Atea\ATimer\år2020\python\versjon2>python RegTimerMain.py
no DB making new now !
Traceback (most recent call last):
  File "C:\Users\brede\OneDrive - Atea\Data\Atea\ATimer\år2020\python\versjon2\dbsqlite.py", line 639, in create_connection
    conn = sqlite3.connect(db_file)
sqlite3.OperationalError: unable to open database file

During handling of the above exception, another exception occurred:

Traceback (most recent call last):
  File "RegTimerMain.py", line 652, in <module>
    vindu = AppMainWindow()
  File "RegTimerMain.py", line 35, in __init__
    new_db = NewDatabase(self.db_file)
  File "C:\Users\brede\OneDrive - Atea\Data\Atea\ATimer\år2020\python\versjon2\dbsqlite.py", line 622, in __init__
    conn=self.create_connection(db_file)
  File "C:\Users\brede\OneDrive - Atea\Data\Atea\ATimer\år2020\python\versjon2\dbsqlite.py", line 641, in create_connection
    except conn.Error as e:
AttributeError: 'NoneType' object has no attribute 'Error'

C:\Users\brede\OneDrive - Atea\Data\Atea\ATimer\år2020\python\versjon2>python RegTimerMain.py
DB OK
QCoreApplication::exec: The event loop is already running
QCoreApplication::exec: The event loop is already running

C:\Users\brede\OneDrive - Atea\Data\Atea\ATimer\år2020\python\versjon2>

pip install openpyxl